Workbook

Sheet Heroes
A1: id | B1: name | C1: role | D1: role2 | E1: offense | F1: ability_effects | G1: durability | H1: difficulty | I1: style1 | J1: style2 | K1: damage_type | L1: range_type | M1: lane1 | N1: lane2 | O1: power_spike | P1: resource | Q1: spike_order
A2: 1 | B2: Miya | C2: Marksman | E2: 70 | F2: 40 | G2: 10 | H2: 10 | I2: DPS | J2: AoE Damage | K2: Physical | L2: Ranged | M2: Gold Lane | O2: Late | P2: Mana | Q2: 5
A3: 2 | B3: Balmond | C3: Fighter | E3: 30 | F3: 20 | G3: 80 | H3: 10 | I3: Sustain | J3: Execute | K3: Physical | L3: Melee | M3: Jungle | N3: EXP Lane | O3: Mid | P3: None | Q3: 3
A4: 3 | B4: Saber | C4: Assassin | E4: 60 | F4: 60 | G4: 20 | H4: 10 | I4: Burst | J4: Targeted CC | K4: Physical | L4: Melee | M4: Jungle | N4: Roaming | O4: Early-Mid | P4: Mana | Q4: 2
A5: 4 | B5: Alice | C5: Mage | E5: 50 | F5: 70 | G5: 50 | H5: 70 | I5: Sustain | J5: AoE Damage | K5: Magic | L5: Melee | M5: EXP Lane | N5: Jungle | O5: Late | P5: None | Q5: 5
A6: 5 | B6: Nana | C6: Mage | E6: 60 | F6: 100 | G6: 50 | H6: 10 | I6: Poke | J6: Soft CC | K6: Magic | L6: Ranged | M6: Mid Lane | O6: Mid | P6: Mana | Q6: 3
A7: 6 | B7: Tigreal | C7: Tank | E7: 10 | F7: 100 | G7: 80 | H7: 10 | I7: AoE CC | J7: Hard CC | K7: Physical | L7: Melee | M7: Roaming | O7: Early-Mid | P7: Mana | Q7: 2
A8: 7 | B8: Alucard | C8: Fighter | D8: Assassin | E8: 50 | F8: 10 | G8: 50 | H8: 40 | I8: Sustain | J8: DPS | K8: Physical | L8: Melee | M8: Jungle | O8: Mid | P8: None | Q8: 3
A9: 8 | B9: Karina | C9: Assassin | E9: 70 | F9: 10 | G9: 50 | H9: 40 | I9: Burst | J9: Execute | K9: Magic | L9: Melee | M9: Jungle | O9: Early-Mid | P9: Mana | Q9: 2
A10: 9 | B10: Akai | C10: Tank | E10: 30 | F10: 90 | G10: 90 | H10: 30 | I10: Hard CC | J10: Shield | K10: Physical | L10: Melee | M10: Roaming | O10: Early-Mid | P10: Mana | Q10: 2
A11: 10 | B11: Franco | C11: Tank | E11: 10 | F11: 100 | G11: 80 | H11: 20 | I11: Targeted CC | J11: Hard CC | K11: Physical | L11: Melee | M11: Roaming | O11: Early-Mid | P11: Mana | Q11: 2
A12: 11 | B12: Bane | C12: Fighter | D12: Mage | E12: 60 | F12: 40 | G12: 50 | H12: 30 | I12: Poke | J12: AoE Damage | K12: Mixed | L12: Melee | M12: Jungle | N12: EXP Lane | O12: Mid | P12: Mana | Q12: 3
A13: 12 | B13: Bruno | C13: Marksman | E13: 60 | F13: 20 | G13: 20 | H13: 50 | I13: DPS | J13: Burst | K13: Physical | L13: Ranged | M13: Gold Lane | O13: Late | P13: Mana | Q13: 5
A14: 13 | B14: Clint | C14: Marksman | E14: 70 | F14: 40 | G14: 30 | H14: 70 | I14: Burst | J14: Poke | K14: Physical | L14: Ranged | M14: Gold Lane | O14: Mid-Late | P14: Mana | Q14: 4
A15: 14 | B15: Rafaela | C15: Support | E15: 20 | F15: 70 | G15: 60 | H15: 20 | I15: Healing | J15: Soft CC | K15: Magic | L15: Ranged | M15: Roaming | O15: Early-Mid | P15: Mana | Q15: 2
A16: 15 | B16: Eudora | C16: Mage | E16: 80 | F16: 80 | G16: 10 | H16: 10 | I16: Burst | J16: Targeted CC | K16: Magic | L16: Ranged | M16: Mid Lane | O16: Mid | P16: Mana | Q16: 3
A17: 16 | B17: Zilong | C17: Fighter | D17: Assassin | E17: 50 | F17: 60 | G17: 20 | H17: 10 | I17: Burst | J17: Mobility | K17: Physical | L17: Melee | M17: EXP Lane | O17: Mid | P17: Mana | Q17: 3
A18: 17 | B18: Fanny | C18: Assassin | E18: 70 | F18: 10 | G18: 60 | H18: 100 | I18: High Mobility | J18: Burst | K18: Physical | L18: Melee | M18: Jungle | O18: Early | P18: Energy | Q18: 1
A19: 18 | B19: Layla | C19: Marksman | E19: 80 | F19: 10 | G19: 10 | H19: 10 | I19: DPS | J19: Poke | K19: Physical | L19: Ranged | M19: Gold Lane | O19: Late | P19: Mana | Q19: 5
A20: 19 | B20: Minotaur | C20: Tank | D20: Support | E20: 10 | F20: 80 | G20: 100 | H20: 40 | I20: AoE CC | J20: Healing | K20: Physical | L20: Melee | M20: Roaming | O20: Mid | P20: None | Q20: 3
A21: 20 | B21: Lolita | C21: Support | D21: Tank | E21: 10 | F21: 90 | G21: 100 | H21: 40 | I21: Shield | J21: AoE CC | K21: Physical | L21: Melee | M21: Roaming | O21: Mid | P21: Mana | Q21: 3
A22: 21 | B22: Hayabusa | C22: Assassin | E22: 50 | F22: 10 | G22: 40 | H22: 50 | I22: Burst | J22: I-Frame | K22: Physical | L22: Melee | M22: Jungle | O22: Early-Mid | P22: Energy | Q22: 2
A23: 22 | B23: Freya | C23: Fighter | E23: 50 | F23: 50 | G23: 60 | H23: 50 | I23: Shield | J23: DPS | K23: Physical | L23: Melee | M23: EXP Lane | N23: Jungle | O23: Mid | P23: None | Q23: 3
A24: 23 | B24: Gord | C24: Mage | E24: 70 | F24: 80 | G24: 10 | H24: 20 | I24: AoE Damage | J24: Poke | K24: Magic | L24: Ranged | M24: Mid Lane | O24: Mid | P24: Mana | Q24: 3
A25: 24 | B25: Natalia | C25: Assassin | E25: 60 | F25: 60 | G25: 10 | H25: 90 | I25: Burst | J25: Vision | K25: Physical | L25: Melee | M25: Jungle | N25: Roaming | O25: Early-Mid | P25: None | Q25: 2
A26: 25 | B26: Kagura | C26: Mage | E26: 90 | F26: 40 | G26: 30 | H26: 80 | I26: Poke | J26: Burst | K26: Magic | L26: Ranged | M26: Mid Lane | O26: Mid | P26: Mana | Q26: 3
A27: 26 | B27: Chou | C27: Fighter | E27: 30 | F27: 80 | G27: 50 | H27: 70 | I27: Hard CC | J27: Dash/Blink | K27: Physical | L27: Melee | M27: EXP Lane | N27: Roaming | O27: Early | P27: None | Q27: 1
A28: 27 | B28: Sun | C28: Fighter | E28: 50 | F28: 10 | G28: 50 | H28: 30 | I28: Summoner | J28: DPS | K28: Physical | L28: Melee | M28: EXP Lane | N28: Jungle | O28: Early-Mid | P28: Mana | Q28: 2
A29: 28 | B29: Alpha | C29: Fighter | E29: 40 | F29: 70 | G29: 60 | H29: 10 | I29: Sustain | J29: True Damage | K29: Physical | L29: Melee | M29: Jungle | N29: EXP Lane | O29: Mid | P29: Mana | Q29: 3
A30: 29 | B30: Ruby | C30: Fighter | E30: 20 | F30: 90 | G30: 90 | H30: 40 | I30: Sustain | J30: AoE CC | K30: Physical | L30: Melee | M30: EXP Lane | O30: Mid-Late | P30: Mana | Q30: 4
A31: 30 | B31: Yi Sun-shin | C31: Assassin | D31: Marksman | E31: 90 | F31: 20 | G31: 40 | H31: 70 | I31: Vision | J31: DPS | K31: Physical | L31: Hybrid | M31: Jungle | O31: Mid-Late | P31: Mana | Q31: 4
A32: 31 | B32: Moskov | C32: Marksman | E32: 60 | F32: 60 | G32: 20 | H32: 50 | I32: DPS | J32: Hard CC | K32: Physical | L32: Ranged | M32: Gold Lane | O32: Late | P32: Mana | Q32: 5
A33: 32 | B33: Johnson | C33: Tank | D33: Support | E33: 30 | F33: 90 | G33: 80 | H33: 50 | I33: Global Dive | J33: AoE CC | K33: Magic | L33: Melee | M33: Roaming | O33: Early-Mid | P33: None | Q33: 2
A34: 33 | B34: Cyclops | C34: Mage | E34: 100 | F34: 70 | G34: 30 | H34: 60 | I34: DPS | J34: Targeted CC | K34: Magic | L34: Ranged | M34: Mid Lane | O34: Mid | P34: Mana | Q34: 3
A35: 34 | B35: Estes | C35: Support | E35: 10 | F35: 20 | G35: 70 | H35: 30 | I35: Healing | J35: Sustain | K35: Magic | L35: Ranged | M35: Roaming | O35: Early-Mid | P35: Mana | Q35: 2
A36: 35 | B36: Hilda | C36: Fighter | D36: Tank | E36: 40 | F36: 40 | G36: 90 | H36: 40 | I36: Sustain | J36: Burst | K36: Physical | L36: Melee | M36: Roaming | N36: EXP Lane | O36: Early | P36: None | Q36: 1
A37: 36 | B37: Aurora | C37: Mage | E37: 70 | F37: 100 | G37: 40 | H37: 10 | I37: Hard CC | J37: Burst | K37: Magic | L37: Ranged | M37: Mid Lane | O37: Mid | P37: Mana | Q37: 3
A38: 37 | B38: Lapu-Lapu | C38: Fighter | E38: 40 | F38: 40 | G38: 80 | H38: 50 | I38: Shield | J38: AoE Damage | K38: Physical | L38: Melee | M38: EXP Lane | O38: Mid | P38: None | Q38: 3
A39: 38 | B39: Vexana | C39: Mage | E39: 90 | F39: 50 | G39: 20 | H39: 10 | I39: Summoner | J39: AoE CC | K39: Magic | L39: Ranged | M39: Mid Lane | O39: Mid | P39: Mana | Q39: 3
A40: 39 | B40: Roger | C40: Fighter | D40: Marksman | E40: 40 | F40: 10 | G40: 60 | H40: 50 | I40: DPS | J40: Mobility | K40: Physical | L40: Hybrid | M40: Jungle | O40: Mid | P40: Mana | Q40: 3
...

Sheet Data-Input
A1: MLBB HERO COUNTER — DATA / INPUT SHEET
A3: This is the ONLY sheet you should manually edit. Shaded yellow cells are safe to change. See the "Documentation - Computations Only" tab for exactly how every formula uses these values.
A5: 1) GLOBAL WEIGHTS / COEFFICIENTS
A6: Coefficient | B6: Value | C6: Description
A7: role_mult | B7: 5 | C7: Multiplier applied to the Role Matchup points (Block 2) to get the Role Advantage score component.
A8: burst_mult | B8: 0.1 | C8: Multiplier applied to (attacker offense + ability_effects)/2 minus defender durability (the "Stat" component).
A9: diff_mult | B9: 0.3 | C9: Multiplier applied to the difficulty gap (attacker difficulty - defender difficulty) when that gap exceeds 20.
A10: style_mult | B10: 5 | C10: Multiplier applied to the Style/Tag Matchup points (Block 5) to get the Style Matchup score component.
A11: spike_mult | B11: 3 | C11: Multiplier applied to the power-spike-order gap (attacker spike order - defender spike order).
A12: dmgtype_same | B12: -2 | C12: Score adjustment when attacker and defender share the same damage type (Physical/Physical or Magic/Magic).
A13: dmgtype_diff | B13: 3 | C13: Score adjustment when attacker and defender have different, non-Mixed damage types.
A14: dmgtype_mixed | B14: 5 | C14: Score adjustment when the attacker's damage type is "Mixed".
A17: 2) ROLE MATCHUP MATRIX (Attacker row -> Defender column, points BEFORE role_mult)
A18: Attacker\Defender | B18: Tank | C18: Fighter | D18: Assassin | E18: Mage | F18: Marksman | G18: Support
A19: Tank | B19: 0 | C19: 0 | D19: 2 | E19: -1 | F19: -1 | G19: -1
A20: Fighter | B20: 0 | C20: 0 | D20: 1 | E20: 1 | F20: 2 | G20: 0
A21: Assassin | B21: -1 | C21: 0 | D21: 0 | E21: 2 | F21: 2 | G21: 1
A22: Mage | B22: 1 | C22: 1 | D22: -1 | E22: 0 | F22: 1 | G22: 0
A23: Marksman | B23: 1 | C23: -1 | D23: -1 | E23: 0 | F23: 0 | G23: 0
A24: Support | B24: -1 | C24: -1 | D24: -2 | E24: -1 | F24: -1 | G24: 0
A27: 3) HARD COUNTER RULES (named-hero or tag-based special matchups — added on top of everything else). Rows 29-128 are dropdown-ready: pick Attacker, ConditionType, and ConditionValue from the lists, just type the row below your last rule.
A28: Attacker | B28: ConditionType (Tag/Hero) | C28: ConditionValue | D28: Bonus_To_Attacker | E28: Penalty_To_Defender | F28: Note
A29: Phoveus | B29: Tag | C29: Dash/Blink | D29: 18 | E29: -25 | F29: Anti-mobility Fighter: Contempt/Soul Reaper marks and executes blink/dash divers who commit onto him.
A30: Phoveus | B30: Tag | C30: High Mobility | D30: 15 | E30: -22 | F30: Punishes sustained-mobility assassins that must stay in his kit range to deal damage.
A31: Phoveus | B31: Tag | C31: Mobility | D31: 10 | E31: -14 | F31: General mobility-tag matchup bonus for Phoveus.
A32: Faramis | B32: Hero | C32: Gloo | D32: 20 | E32: -18 | F32: Faramis' ultimate burst plus Army of the Dead shred Gloo's split-body sustain before he can re-form.
A33: Franco | B33: Tag | C33: Dash/Blink | D33: 10 | E33: -12 | F33: Iron Hook interrupts dash/blink animations and yanks divers out of position.
A34: Khufra | B34: Tag | C34: Dash/Blink | D34: 14 | E34: -18 | F34: Bouncing Ball cancels dashes/blinks mid-animation, hard-locking mobility divers.
A35: Khufra | B35: Tag | C35: High Mobility | D35: 12 | E35: -15 | F35: Sturdiness plus Charging Roar punish sustained-mobility assassins.
A36: Lolita | B36: Tag | C36: Global Dive | D36: 15 | E36: -20 | F36: Shield absorbs global ultimates and burst combos, hard-countering dive compositions.
A37: Diggie | B37: Tag | C37: Hard CC | D37: 12 | E37: -15 | F37: Reverse Delay and Time Journey purge crowd control, hard-countering CC-reliant heroes.
A38: Baxia | B38: Tag | C38: AoE Damage | D38: 12 | E38: -15 | F38: Aegis shield mitigates AoE poke/damage compositions.
A39: Baxia | B39: Tag | C39: Poke | D39: 10 | E39: -12 | F39: Damage reduction plus anti-heal wear down poke comps over time.
A40: Helcurt | B40: Tag | C40: Poke | D40: 12 | E40: -14 | F40: Stealth and silence punish backline poke mages before they can kite.
A41: Ruby | B41: Tag | C41: Dash/Blink | D41: 8 | E41: -10 | F41: Ruby's leash/pull chains punish overextending dash divers.
A42: Saber | B42: Hero | C42: Fanny | D42: 20 | E42: -20
A131: 4) TAG GLOSSARY / REFERENCE (informational — the 22 tags marked "In-use" are wired into Block 5 below)
A132: Category | B132: Tag | C132: Description | D132: Example Heroes | E132: Status
A133: Damage Profile | B133: Burst | C133: High, immediate damage designed to delete squishy targets. | D133: Saber, Eudora, Kadita | E133: In-use
A134: Damage Profile | B134: DPS | C134: Sustained, continuous damage over time, usually from basic attacks. | D134: Miya, Claude, Moskov | E134: In-use
...

Sheet Documentation - Computations
A1: MLBB HERO COUNTER MODEL — COMPUTATIONS ONLY
A3: This sheet explains ONLY how the numbers are calculated — the tag/point system, role weights, and the exact formulas — so you can edit the logic yourself later. All values that formulas read from live in the "Data-Input" sheet. Never hardcode a number into a formula; if a number needs to change, change it in Data-Input.
A5: 1. WORKBOOK MAP
A7: • Heroes — one row per hero: role/role2, base stats (offense, ability_effects, durability, difficulty), and TAGS (style1/style2), damage_type, lane, power_spike/spike_order. This is the raw data. Not touched by this update.
A8: • Data-Input — the ONLY sheet you should edit. Contains: Global Weights, Role Matchup Matrix, Hard Counter Rules, Tag Glossary, Style/Tag Interaction Matrix, and Manual Overrides.
A9: • CounterCalculator — pick one Attacker + one Defender (dropdowns) and see a full component-by-component score breakdown.
A10: • LookupCalc — a hidden-ish engine sheet that computes the SAME score for all 133 heroes as candidate Attackers against whichever Defender is chosen on the Lookup sheet (cell Lookup!A1). This powers the Top-5 tables.
A11: • Lookup — pick a hero in A1 and see the Top 5 overall counters, plus Top 5 counters who also share that hero's lane.
A13: 2. WHAT "TAGS" MEANS IN THIS MODEL
A15: Every hero has up to two tags: Heroes!style1 and Heroes!style2 (e.g. "Dash/Blink", "Burst", "Sustain", "Hard CC"). These are the hero's stylistic identity — how it deals damage, controls fights, and moves. The Data-Input Tag Glossary (Block 4) lists every known tag; the 22 tags marked "In-use" are the ones wired into the Style/Tag Interaction Matrix (Block 5) and therefore actually move the score. Tags marked "Fandom wiki" are reference-only and are not yet scored — promote one by adding it as a new row+column in Block 5.
A17: 3. THE COUNTER SCORE FORMULA
A19: TOTAL COUNTER SCORE = Role Advantage + Stat + Difficulty Gap + Damage Type Advantage + Power Spike Timing + Style Matchup + Hard Counter Bonus (then a Manual Override, if one exists for that exact pair, replaces this entire total).
... A84: ☐ Add a brand-new tag → give it a row AND column in Data-Input Block 5, and add it to the Tag Glossary in Block 4 for documentation purposes.

Sheet CounterCalculator
A1: MLBB Counter Calculator
G2: ATTACKER (auto) | J2: DEFENDER (auto) | M2: WEIGHTS (auto)
A3: Attacker: | C3: Defender: | G3: Role | H3: =IFERROR(INDEX(Heroes!$C$2:$C$134,MATCH($B$3,Heroes!$B$2:$B$134,0)),"") | J3: Role | K3: =IFERROR(INDEX(Heroes!$C$2:$C$134,MATCH($D$3,Heroes!$B$2:$B$134,0)),"") | M3: role_mult | N3: =IFERROR(INDEX('Data-Input'!$B$7:$B$14,MATCH("role_mult",'Data-Input'!$A$7:$A$14,0)),5) -> 5
G4: Role2 | H4: =IFERROR(INDEX(Heroes!$D$2:$D$134,MATCH($B$3,Heroes!$B$2:$B$134,0)),"") | J4: Role2 | K4: =IFERROR(INDEX(Heroes!$D$2:$D$134,MATCH($D$3,Heroes!$B$2:$B$134,0)),"") | M4: burst_mult | N4: =IFERROR(INDEX('Data-Input'!$B$7:$B$14,MATCH("burst_mult",'Data-Input'!$A$7:$A$14,0)),0.1) -> 0.1
A5: Score Breakdown | G5: Offense | H5: =IFERROR(INDEX(Heroes!$E$2:$E$134,MATCH($B$3,Heroes!$B$2:$B$134,0)),"") | J5: Durability | K5: =IFERROR(INDEX(Heroes!$G$2:$G$134,MATCH($D$3,Heroes!$B$2:$B$134,0)),"") | M5: diff_mult | N5: =IFERROR(INDEX('Data-Input'!$B$7:$B$14,MATCH("diff_mult",'Data-Input'!$A$7:$A$14,0)),0.3) -> 0.3
B6: Component | C6: Value | G6: Ability Effects | H6: =IFERROR(INDEX(Heroes!$F$2:$F$134,MATCH($B$3,Heroes!$B$2:$B$134,0)),"") | J6: Difficulty | K6: =IFERROR(INDEX(Heroes!$H$2:$H$134,MATCH($D$3,Heroes!$B$2:$B$134,0)),"") | M6: style_mult | N6: =IFERROR(INDEX('Data-Input'!$B$7:$B$14,MATCH("style_mult",'Data-Input'!$A$7:$A$14,0)),5) -> 5
B7: Role Advantage | C7: =IF(OR($B$3="",$D$3=""),0,MAX(IFERROR(INDEX('Data-Input'!$B$19:$G$24,MATCH($H$3,'Data-Input'!$A$19:$A$24,0),MATCH($K$3,'Data-Input'!$B$18:$G$18,0)),0),IF($H$4<>"",IFERROR(INDEX('Data-Input'!$B$19:$G$24,MATCH($H$4,'Data-Input'!$A$19:$A$24,0),MATCH($K$3,'Data-Input'!$B$18:$G$18,0)),0),IFERROR(INDEX('Data-Input'!$B$19:$G$24,MATCH($H$3,'Data-Input'!$A$19:$A$24,0),MATCH($K$3,'Data-Input'!$B$18:$G$18,0)),0)))*$N$3) -> 0 | G7: Difficulty | H7: =IFERROR(INDEX(Heroes!$H$2:$H$134,MATCH($B$3,Heroes!$B$2:$B$134,0)),"") | J7: Style1 | K7: =IFERROR(INDEX(Heroes!$I$2:$I$134,MATCH($D$3,Heroes!$B$2:$B$134,0)),"") | M7: spike_mult | N7: =IFERROR(INDEX('Data-Input'!$B$7:$B$14,MATCH("spike_mult",'Data-Input'!$A$7:$A$14,0)),3) -> 3
B8: Stat (Burst vs Durability) | C8: =IF(OR($B$3="",$D$3=""),0,(($H$5+$H$6)/2-$K$5)*$N$4) -> 0 | G8: Style1 | H8: =IFERROR(INDEX(Heroes!$I$2:$I$134,MATCH($B$3,Heroes!$B$2:$B$134,0)),"") | J8: Style2 | K8: =IFERROR(INDEX(Heroes!$J$2:$J$134,MATCH($D$3,Heroes!$B$2:$B$134,0)),"") | M8: dmgtype_same | N8: =IFERROR(INDEX('Data-Input'!$B$7:$B$14,MATCH("dmgtype_same",'Data-Input'!$A$7:$A$14,0)),-2) -> -2
B9: Difficulty Gap | C9: =IF(OR($B$3="",$D$3=""),0,IF(($H$7-$K$6)>20,($H$7-$K$6)*$N$5,0)) -> 0 | G9: Style2 | H9: =IFERROR(INDEX(Heroes!$J$2:$J$134,MATCH($B$3,Heroes!$B$2:$B$134,0)),"") | J9: Damage Type | K9: =IFERROR(INDEX(Heroes!$K$2:$K$134,MATCH($D$3,Heroes!$B$2:$B$134,0)),"") | M9: dmgtype_diff | N9: =IFERROR(INDEX('Data-Input'!$B$7:$B$14,MATCH("dmgtype_diff",'Data-Input'!$A$7:$A$14,0)),3) -> 3
B10: Damage Type Advantage | C10: =IF(OR($B$3="",$D$3=""),0,IF($H$10="Mixed",$N$10,IF($H$10=$K$9,$N$8,$N$9))) -> 0 | G10: Damage Type | H10: =IFERROR(INDEX(Heroes!$K$2:$K$134,MATCH($B$3,Heroes!$B$2:$B$134,0)),"") | J10: Spike Order | K10: =IFERROR(INDEX(Heroes!$Q$2:$Q$134,MATCH($D$3,Heroes!$B$2:$B$134,0)),"") | M10: dmgtype_mixed | N10: =IFERROR(INDEX('Data-Input'!$B$7:$B$14,MATCH("dmgtype_mixed",'Data-Input'!$A$7:$A$14,0)),5) -> 5
B11: Power Spike Timing | C11: =IF(OR($B$3="",$D$3=""),0,($H$11-$K$10)*$N$7) -> 0 | G11: Spike Order | H11: =IFERROR(INDEX(Heroes!$Q$2:$Q$134,MATCH($B$3,Heroes!$B$2:$B$134,0)),"")
B12: Style Matchup | C12: =IF(OR($B$3="",$D$3=""),0,MAX(IF($H$8<>"",IFERROR(INDEX('Data-Input'!$B$164:$W$185,MATCH($H$8,'Data-Input'!$A$164:$A$185,0),MATCH($K$7,'Data-Input'!$B$163:$W$163,0)),0),0),IF(AND($H$8<>"",$K$8<>""),IFERROR(INDEX('Data-Input'!$B$164:$W$185,MATCH($H$8,'Data-Input'!$A$164:$A$185,0),MATCH($K$8,'Data-Input'!$B$163:$W$163,0)),0),0),IF($H$9<>"",IFERROR(INDEX('Data-Input'!$B$164:$W$185,MATCH($H$9,'Data-Input'!$A$164:$A$185,0),MATCH($K$7,'Data-Input'!$B$163:$W$163,0)),0),0),IF(AND($H$9<>"",$K$8<>""),IFERROR(INDEX('Data-Input'!$B$164:$W$185,MATCH($H$9,'Data-Input'!$A$164:$A$185,0),MATCH($K$8,'Data-Input'!$B$163:$W$163,0)),0),0))*$N$6) -> 0
B13: Hard Counter Bonus (named-hero / tag rules) | C13: =IF(OR($B$3="",$D$3=""),0,SUMPRODUCT(('Data-Input'!$A$29:$A$128=$B$3)*('Data-Input'!$B$29:$B$128="Tag")*((( 'Data-Input'!$C$29:$C$128=$K$7)+('Data-Input'!$C$29:$C$128=$K$8))>0)*('Data-Input'!$D$29:$D$128-'Data-Input'!$E$29:$E$128))+SUMPRODUCT(('Data-Input'!$A$29:$A$128=$B$3)*('Data-Input'!$B$29:$B$128="Hero")*('Data-Input'!$C$29:$C$128=$D$3)*('Data-Input'!$D$29:$D$128-'Data-Input'!$E$29:$E$128))) -> 0
B14: Base Total (sum of components) | C14: =SUM(C7:C13) -> 0
B15: Manual Override | C15: =IFERROR(INDEX('Data-Input'!$C$190:$C$1189,MATCH($B$3&"|"&$D$3,'Data-Input'!$E$190:$E$1189,0)),"None") -> 0
B17: TOTAL COUNTER SCORE | C17: =IF(OR($B$3="",$D$3=""),"",IF(C15="None",C14,C15))
A19: Tip: pick heroes in B3 (Attacker) and D3 (Defender) above. Positive score = Attacker counters Defender. Row 13 reflects any named Hard Counter Rule (see Data-Input, Block 3).

Sheet Lookup
B1: Top 5 — Overall Counters
B2: Counter Name | C2: Score
B3: =IFERROR(INDEX(LookupCalc!$A$2:$A$134,MATCH(LARGE(LookupCalc!$T$2:$T$134,ROW()-2),LookupCalc!$T$2:$T$134,0)),"") -> Lunox | C3: =IFERROR(ROUND(LARGE(LookupCalc!$T$2:$T$134,ROW()-2),2),"") -> 50.5
B4: =IFERROR(INDEX(LookupCalc!$A$2:$A$134,MATCH(LARGE(LookupCalc!$T$2:$T$134,ROW()-2),LookupCalc!$T$2:$T$134,0)),"") -> Alice | C4: =IFERROR(ROUND(LARGE(LookupCalc!$T$2:$T$134,ROW()-2),2),"") -> 45
B5: =IFERROR(INDEX(LookupCalc!$A$2:$A$134,MATCH(LARGE(LookupCalc!$T$2:$T$134,ROW()-2),LookupCalc!$T$2:$T$134,0)),"") -> Valentina | C5: =IFERROR(ROUND(LARGE(LookupCalc!$T$2:$T$134,ROW()-2),2),"") -> 44.5
B6: =IFERROR(INDEX(LookupCalc!$A$2:$A$134,MATCH(LARGE(LookupCalc!$T$2:$T$134,ROW()-2),LookupCalc!$T$2:$T$134,0)),"") -> Kimmy | C6: =IFERROR(ROUND(LARGE(LookupCalc!$T$2:$T$134,ROW()-2),2),"") -> 44.5
B7: =IFERROR(INDEX(LookupCalc!$A$2:$A$134,MATCH(LARGE(LookupCalc!$T$2:$T$134,ROW()-2),LookupCalc!$T$2:$T$134,0)),"") -> Kagura | C7: =IFERROR(ROUND(LARGE(LookupCalc!$T$2:$T$134,ROW()-2),2),"") -> 42.5
B9: =IF($A$1="","Top 5 — Same Lane","Top 5 — Same Lane ("&IFERROR(INDEX(Heroes!$M$2:$M$134,MATCH($A$1,Heroes!$B$2:$B$134,0)),"?")&")") -> Top 5 — Same Lane
B10: Counter Name | C10: Score
B11: =IFERROR(INDEX(LookupCalc!$A$2:$A$134,MATCH(LARGE(LookupCalc!$V$2:$V$134,ROW()-10),LookupCalc!$V$2:$V$134,0)),"") -> Miya | C11: =IFERROR(ROUND(LARGE(LookupCalc!$V$2:$V$134,ROW()-10),2),"") -> -1e+15
B12: =IFERROR(INDEX(LookupCalc!$A$2:$A$134,MATCH(LARGE(LookupCalc!$V$2:$V$134,ROW()-10),LookupCalc!$V$2:$V$134,0)),"") -> Miya | C12: =IFERROR(ROUND(LARGE(LookupCalc!$V$2:$V$134,ROW()-10),2),"") -> -1e+15
B13: =IFERROR(INDEX(LookupCalc!$A$2:$A$134,MATCH(LARGE(LookupCalc!$V$2:$V$134,ROW()-10),LookupCalc!$V$2:$V$134,0)),"") -> Miya | C13: =IFERROR(ROUND(LARGE(LookupCalc!$V$2:$V$134,ROW()-10),2),"") -> -1e+15
B14: =IFERROR(INDEX(LookupCalc!$A$2:$A$134,MATCH(LARGE(LookupCalc!$V$2:$V$134,ROW()-10),LookupCalc!$V$2:$V$134,0)),"") -> Miya | C14: =IFERROR(ROUND(LARGE(LookupCalc!$V$2:$V$134,ROW()-10),2),"") -> -1e+15
B15: =IFERROR(INDEX(LookupCalc!$A$2:$A$134,MATCH(LARGE(LookupCalc!$V$2:$V$134,ROW()-10),LookupCalc!$V$2:$V$134,0)),"") -> Miya | C15: =IFERROR(ROUND(LARGE(LookupCalc!$V$2:$V$134,ROW()-10),2),"") -> -1e+15

Sheet LookupCalc
A1: =Lookup!$A$1 -> 0 | B1: =IFERROR(INDEX(Heroes!$C$2:$C$134,MATCH($A$1,Heroes!$B$2:$B$134,0)),"") | C1: =IFERROR(INDEX(Heroes!$G$2:$G$134,MATCH($A$1,Heroes!$B$2:$B$134,0)),0) -> 0 | D1: =IFERROR(INDEX(Heroes!$H$2:$H$134,MATCH($A$1,Heroes!$B$2:$B$134,0)),0) -> 0 | E1: =IFERROR(INDEX(Heroes!$K$2:$K$134,MATCH($A$1,Heroes!$B$2:$B$134,0)),"") | F1: =IFERROR(INDEX(Heroes!$Q$2:$Q$134,MATCH($A$1,Heroes!$B$2:$B$134,0)),0) -> 0 | G1: =IFERROR(INDEX('Data-Input'!$B$7:$B$14,MATCH("role_mult",'Data-Input'!$A$7:$A$14,0)),5) -> 5 | H1: =IFERROR(INDEX('Data-Input'!$B$7:$B$14,MATCH("burst_mult",'Data-Input'!$A$7:$A$14,0)),0.1) -> 0.1 | I1: =IFERROR(INDEX('Data-Input'!$B$7:$B$14,MATCH("diff_mult",'Data-Input'!$A$7:$A$14,0)),0.3) -> 0.3 | J1: =IFERROR(INDEX(Heroes!$M$2:$M$134,MATCH($A$1,Heroes!$B$2:$B$134,0)),"") | K1: =IFERROR(INDEX(Heroes!$I$2:$I$134,MATCH($A$1,Heroes!$B$2:$B$134,0)),"") | L1: =IFERROR(INDEX(Heroes!$J$2:$J$134,MATCH($A$1,Heroes!$B$2:$B$134,0)),"") | M1: =IFERROR(INDEX('Data-Input'!$B$7:$B$14,MATCH("style_mult",'Data-Input'!$A$7:$A$14,0)),5) -> 5 | N1: =IFERROR(INDEX('Data-Input'!$B$7:$B$14,MATCH("spike_mult",'Data-Input'!$A$7:$A$14,0)),3) -> 3 | O1: =IFERROR(INDEX('Data-Input'!$B$7:$B$14,MATCH("dmgtype_same",'Data-Input'!$A$7:$A$14,0)),-2) -> -2 | P1: =IFERROR(INDEX('Data-Input'!$B$7:$B$14,MATCH("dmgtype_diff",'Data-Input'!$A$7:$A$14,0)),3) -> 3 | Q1: =IFERROR(INDEX('Data-Input'!$B$7:$B$14,MATCH("dmgtype_mixed",'Data-Input'!$A$7:$A$14,0)),5) -> 5 | U1: Lane1 (helper) | V1: Lane Sort Key (helper) | W1: Style1 (helper) | X1: Style2 (helper) | Y1: Style Matchup (component) | Z1: Hard Counter Bonus (component)
A2: =Heroes!$B2 -> Miya | B2: =Heroes!$C2 -> Marksman | C2: =Heroes!$D2 -> 0 | D2: =Heroes!$E2 -> 70 | E2: =Heroes!$F2 -> 40 | F2: =Heroes!$H2 -> 10 | G2: =Heroes!$K2 -> Physical | H2: =Heroes!$Q2 -> 5 | I2: =IFERROR(INDEX('Data-Input'!$B$19:$G$24,MATCH(B2,'Data-Input'!$A$19:$A$24,0),MATCH($B$1,'Data-Input'!$B$18:$G$18,0)),0) -> 0 | J2: =IF(C2<>"",IFERROR(INDEX('Data-Input'!$B$19:$G$24,MATCH(C2,'Data-Input'!$A$19:$A$24,0),MATCH($B$1,'Data-Input'!$B$18:$G$18,0)),0),I2) -> 0 | K2: =MAX(I2,J2) -> 0 | L2: =((D2+E2)/2-$C$1)*$H$1 -> 5.5 | M2: =F2-$D$1 -> 10 | N2: =IF(M2>20,M2*$I$1,0) -> 0 | O2: =IF(G2="Mixed",$Q$1,IF(G2=$E$1,$O$1,$P$1)) -> 3 | P2: =(H2-$F$1)*$N$1 -> 15 | Q2: =K2*$G$1+L2+N2+O2+P2+Y2+Z2 -> 23.5 | R2: =IFERROR(INDEX('Data-Input'!$C$190:$C$1189,MATCH(A2&"|"&$A$1,'Data-Input'!$E$190:$E$1189,0)),Q2) -> 23.5 | S2: =IF(OR($A$1="",A2=$A$1),-1000000000000000,R2) -> 23.5 | T2: =S2+ROW()*0.0000001 -> 23.5 | U2: =Heroes!$M2 -> Gold Lane | V2: =IF(OR($A$1="",A2=$A$1,U2="",U2<>$J$1),-1000000000000000,R2)+ROW()*0.0000001 -> -1e+15 | W2: =Heroes!$I2 -> DPS | X2: =Heroes!$J2 -> AoE Damage | Y2: =IF($A$1="",0,MAX(IF(W2<>"",IFERROR(INDEX('Data-Input'!$B$164:$W$185,MATCH(W2,'Data-Input'!$A$164:$A$185,0),MATCH($K$1,'Data-Input'!$B$163:$W$163,0)),0),0),IF(AND(W2<>"",$L$1<>""),IFERROR(INDEX('Data-Input'!$B$164:$W$185,MATCH(W2,'Data-Input'!$A$164:$A$185,0),MATCH($L$1,'Data-Input'!$B$163:$W$163,0)),0),0),IF(X2<>"",IFERROR(INDEX('Data-Input'!$B$164:$W$185,MATCH(X2,'Data-Input'!$A$164:$A$185,0),MATCH($K$1,'Data-Input'!$B$163:$W$163,0)),0),0),IF(AND(X2<>"",$L$1<>""),IFERROR(INDEX('Data-Input'!$B$164:$W$185,MATCH(X2,'Data-Input'!$A$164:$A$185,0),MATCH($L$1,'Data-Input'!$B$163:$W$163,0)),0),0))*$M$1) -> 0 | Z2: =IF($A$1="",0,SUMPRODUCT(('Data-Input'!$A$29:$A$128=A2)*('Data-Input'!$B$29:$B$128="Tag")*((('Data-Input'!$C$29:$C$128=$K$1)+('Data-Input'!$C$29:$C$128=$L$1))>0)*('Data-Input'!$D$29:$D$128-'Data-Input'!$E$29:$E$128))+SUMPRODUCT(('Data-Input'!$A$29:$A$128=A2)*('Data-Input'!$B$29:$B$128="Hero")*('Data-Input'!$C$29:$C$128=$A$1)*('Data-Input'!$D$29:$D$128-'Data-Input'!$E$29:$E$128))) -> 0
A3: =Heroes!$B3 -> Balmond | B3: =Heroes!$C3 -> Fighter | C3: =Heroes!$D3 -> 0 | D3: =Heroes!$E3 -> 30 | E3: =Heroes!$F3 -> 20 | F3: =Heroes!$H3 -> 10 | G3: =Heroes!$K3 -> Physical | H3: =Heroes!$Q3 -> 3 | I3: =IFERROR(INDEX('Data-Input'!$B$19:$G$24,MATCH(B3,'Data-Input'!$A$19:$A$24,0),MATCH($B$1,'Data-Input'!$B$18:$G$18,0)),0) -> 0 | J3: =IF(C3<>"",IFERROR(INDEX('Data-Input'!$B$19:$G$24,MATCH(C3,'Data-Input'!$A$19:$A$24,0),MATCH($B$1,'Data-Input'!$B$18:$G$18,0)),0),I3) -> 0 | K3: =MAX(I3,J3) -> 0 | L3: =((D3+E3)/2-$C$1)*$H$1 -> 2.5 | M3: =F3-$D$1 -> 10 | N3: =IF(M3>20,M3*$I$1,0) -> 0 | O3: =IF(G3="Mixed",$Q$1,IF(G3=$E$1,$O$1,$P$1)) -> 3 | P3: =(H3-$F$1)*$N$1 -> 9 | Q3: =K3*$G$1+L3+N3+O3+P3+Y3+Z3 -> 14.5 | R3: =IFERROR(INDEX('Data-Input'!$C$190:$C$1189,MATCH(A3&"|"&$A$1,'Data-Input'!$E$190:$E$1189,0)),Q3) -> 14.5 | S3: =IF(OR($A$1="",A3=$A$1),-1000000000000000,R3) -> 14.5 | T3: =S3+ROW()*0.0000001 -> 14.5 | U3: =Heroes!$M3 -> Jungle | V3: =IF(OR($A$1="",A3=$A$1,U3="",U3<>$J$1),-1000000000000000,R3)+ROW()*0.0000001 -> -1e+15 | W3: =Heroes!$I3 -> Sustain | X3: =Heroes!$J3 -> Execute | Y3: =IF($A$1="",0,MAX(IF(W3<>"",IFERROR(INDEX('Data-Input'!$B$164:$W$185,MATCH(W3,'Data-Input'!$A$164:$A$185,0),MATCH($K$1,'Data-Input'!$B$163:$W$163,0)),0),0),IF(AND(W3<>"",$L$1<>""),IFERROR(INDEX('Data-Input'!$B$164:$W$185,MATCH(W3,'Data-Input'!$A$164:$A$185,0),MATCH($L$1,'Data-Input'!$B$163:$W$163,0)),0),0),IF(X3<>"",IFERROR(INDEX('Data-Input'!$B$164:$W$185,MATCH(X3,'Data-Input'!$A$164:$A$185,0),MATCH($K$1,'Data-Input'!$B$163:$W$163,0)),0),0),IF(AND(X3<>"",$L$1<>""),IFERROR(INDEX('Data-Input'!$B$164:$W$185,MATCH(X3,'Data-Input'!$A$164:$A$185,0),MATCH($L$1,'Data-Input'!$B$163:$W$163,0)),0),0))*$M$1) -> 0 | Z3: =IF($A$1="",0,SUMPRODUCT(('Data-Input'!$A$29:$A$128=A3)*('Data-Input'!$B$29:$B$128="Tag")*((('Data-Input'!$C$29:$C$128=$K$1)+('Data-Input'!$C$29:$C$128=$L$1))>0)*('Data-Input'!$D$29:$D$128-'Data-Input'!$E$29:$E$128))+SUMPRODUCT(('Data-Input'!$A$29:$A$128=A3)*('Data-Input'!$B$29:$B$128="Hero")*('Data-Input'!$C$29:$C$128=$A$1)*('Data-Input'!$D$29:$D$128-'Data-Input'!$E$29:$E$128))) -> 0
A4: =Heroes!$B4 -> Saber | B4: =Heroes!$C4 -> Assassin | C4: =Heroes!$D4 -> 0 | D4: =Heroes!$E4 -> 60 | E4: =Heroes!$F4 -> 60 | F4: =Heroes!$H4 -> 10 | G4: =Heroes!$K4 -> Physical | H4: =Heroes!$Q4 -> 2 | I4: =IFERROR(INDEX('Data-Input'!$B$19:$G$24,MATCH(B4,'Data-Input'!$A$19:$A$24,0),MATCH($B$1,'Data-Input'!$B$18:$G$18,0)),0) -> 0 | J4: =IF(C4<>"",IFERROR(INDEX('Data-Input'!$B$19:$G$24,MATCH(C4,'Data-Input'!$A$19:$A$24,0),MATCH($B$1,'Data-Input'!$B$18:$G$18,0)),0),I4) -> 0 | K4: =MAX(I4,J4) -> 0 | L4: =((D4+E4)/2-$C$1)*$H$1 -> 6 | M4: =F4-$D$1 -> 10 | N4: =IF(M4>20,M4*$I$1,0) -> 0 | O4: =IF(G4="Mixed",$Q$1,IF(G4=$E$1,$O$1,$P$1)) -> 3 | P4: =(H4-$F$1)*$N$1 -> 6 | Q4: =K4*$G$1+L4+N4+O4+P4+Y4+Z4 -> 15 | R4: =IFERROR(INDEX('Data-Input'!$C$190:$C$1189,MATCH(A4&"|"&$A$1,'Data-Input'!$E$190:$E$1189,0)),Q4) -> 15 | S4: =IF(OR($A$1="",A4=$A$1),-1000000000000000,R4) -> 15 | T4: =S4+ROW()*0.0000001 -> 15 | U4: =Heroes!$M4 -> Jungle | V4: =IF(OR($A$1="",A4=$A$1,U4="",U4<>$J$1),-1000000000000000,R4)+ROW()*0.0000001 -> -1e+15 | W4: =Heroes!$I4 -> Burst | X4: =Heroes!$J4 -> Targeted CC | Y4: =IF($A$1="",0,MAX(IF(W4<>"",IFERROR(INDEX('Data-Input'!$B$164:$W$185,MATCH(W4,'Data-Input'!$A$164:$A$185,0),MATCH($K$1,'Data-Input'!$B$163:$W$163,0)),0),0),IF(AND(W4<>"",$L$1<>""),IFERROR(INDEX('Data-Input'!$B$164:$W$185,MATCH(W4,'Data-Input'!$A$164:$A$185,0),MATCH($L$1,'Data-Input'!$B$163:$W$163,0)),0),0),IF(X4<>"",IFERROR(INDEX('Data-Input'!$B$164:$W$185,MATCH(X4,'Data-Input'!$A$164:$A$185,0),MATCH($K$1,'Data-Input'!$B$163:$W$163,0)),0),0),IF(AND(X4<>"",$L$1<>""),IFERROR(INDEX('Data-Input'!$B$164:$W$185,MATCH(X4,'Data-Input'!$A$164:$A$185,0),MATCH($L$1,'Data-Input'!$B$163:$W$163,0)),0),0))*$M$1) -> 0 | Z4: =IF($A$1="",0,SUMPRODUCT(('Data-Input'!$A$29:$A$128=A4)*('Data-Input'!$B$29:$B$128="Tag")*((('Data-Input'!$C$29:$C$128=$K$1)+('Data-Input'!$C$29:$C$128=$L$1))>0)*('Data-Input'!$D$29:$D$128-'Data-Input'!$E$29:$E$128))+SUMPRODUCT(('Data-Input'!$A$29:$A$128=A4)*('Data-Input'!$B$29:$B$128="Hero")*('Data-Input'!$C$29:$C$128=$A$1)*('Data-Input'!$D$29:$D$128-'Data-Input'!$E$29:$E$128))) -> 0
A5: =Heroes!$B5 -> Alice | B5: =Heroes!$C5 -> Mage | C5: =Heroes!$D5 -> 0 | D5: =Heroes!$E5 -> 50 | E5: =Heroes!$F5 -> 70 | F5: =Heroes!$H5 -> 70 | G5: =Heroes!$K5 -> Magic | H5: =Heroes!$Q5 -> 5 | I5: =IFERROR(INDEX('Data-Input'!$B$19:$G$24,MATCH(B5,'Data-Input'!$A$19:$A$24,0),MATCH($B$1,'Data-Input'!$B$18:$G$18,0)),0) -> 0 | J5: =IF(C5<>"",IFERROR(INDEX('Data-Input'!$B$19:$G$24,MATCH(C5,'Data-Input'!$A$19:$A$24,0),MATCH($B$1,'Data-Input'!$B$18:$G$18,0)),0),I5) -> 0 | K5: =MAX(I5,J5) -> 0 | L5: =((D5+E5)/2-$C$1)*$H$1 -> 6 | M5: =F5-$D$1 -> 70 | N5: =IF(M5>20,M5*$I$1,0) -> 21 | O5: =IF(G5="Mixed",$Q$1,IF(G5=$E$1,$O$1,$P$1)) -> 3 | P5: =(H5-$F$1)*$N$1 -> 15 | Q5: =K5*$G$1+L5+N5+O5+P5+Y5+Z5 -> 45 | R5: =IFERROR(INDEX('Data-Input'!$C$190:$C$1189,MATCH(A5&"|"&$A$1,'Data-Input'!$E$190:$E$1189,0)),Q5) -> 45 | S5: =IF(OR($A$1="",A5=$A$1),-1000000000000000,R5) -> 45 | T5: =S5+ROW()*0.0000001 -> 45 | U5: =Heroes!$M5 -> EXP Lane | V5: =IF(OR($A$1="",A5=$A$1,U5="",U5<>$J$1),-1000000000000000,R5)+ROW()*0.0000001 -> -1e+15 | W5: =Heroes!$I5 -> Sustain | X5: =Heroes!$J5 -> AoE Damage | Y5: =IF($A$1="",0,MAX(IF(W5<>"",IFERROR(INDEX('Data-Input'!$B$164:$W$185,MATCH(W5,'Data-Input'!$A$164:$A$185,0),MATCH($K$1,'Data-Input'!$B$163:$W$163,0)),0),0),IF(AND(W5<>"",$L$1<>""),IFERROR(INDEX('Data-Input'!$B$164:$W$185,MATCH(W5,'Data-Input'!$A$164:$A$185,0),MATCH($L$1,'Data-Input'!$B$163:$W$163,0)),0),0),IF(X5<>"",IFERROR(INDEX('Data-Input'!$B$164:$W$185,MATCH(X5,'Data-Input'!$A$164:$A$185,0),MATCH($K$1,'Data-Input'!$B$163:$W$163,0)),0),0),IF(AND(X5<>"",$L$1<>""),IFERROR(INDEX('Data-Input'!$B$164:$W$185,MATCH(X5,'Data-Input'!$A$164:$A$185,0),MATCH($L$1,'Data-Input'!$B$163:$W$163,0)),0),0))*$M$1) -> 0 | Z5: =IF($A$1="",0,SUMPRODUCT(('Data-Input'!$A$29:$A$128=A5)*('Data-Input'!$B$29:$B$128="Tag")*((('Data-Input'!$C$29:$C$128=$K$1)+('Data-Input'!$C$29:$C$128=$L$1))>0)*('Data-Input'!$D$29:$D$128-'Data-Input'!$E$29:$E$128))+SUMPRODUCT(('Data-Input'!$A$29:$A$128=A5)*('Data-Input'!$B$29:$B$128="Hero")*('Data-Input'!$C$29:$C$128=$A$1)*('Data-Input'!$D$29:$D$128-'Data-Input'!$E$29:$E$128))) -> 0
A6: =Heroes!$B6 -> Nana | B6: =Heroes!$C6 -> Mage | C6: =Heroes!$D6 -> 0 | D6: =Heroes!$E6 -> 60 | E6: =Heroes!$F6 -> 100 | F6: =Heroes!$H6 -> 10 | G6: =Heroes!$K6 -> Magic | H6: =Heroes!$Q6 -> 3 | I6: =IFERROR(INDEX('Data-Input'!$B$19:$G$24,MATCH(B6,'Data-Input'!$A$19:$A$24,0),MATCH($B$1,'Data-Input'!$B$18:$G$18,0)),0) -> 0 | J6: =IF(C6<>"",IFERROR(INDEX('Data-Input'!$B$19:$G$24,MATCH(C6,'Data-Input'!$A$19:$A$24,0),MATCH($B$1,'Data-Input'!$B$18:$G$18,0)),0),I6) -> 0 | K6: =MAX(I6,J6) -> 0 | L6: =((D6+E6)/2-$C$1)*$H$1 -> 8 | M6: =F6-$D$1 -> 10 | N6: =IF(M6>20,M6*$I$1,0) -> 0 | O6: =IF(G6="Mixed",$Q$1,IF(G6=$E$1,$O$1,$P$1)) -> 3 | P6: =(H6-$F$1)*$N$1 -> 9 | Q6: =K6*$G$1+L6+N6+O6+P6+Y6+Z6 -> 20 | R6: =IFERROR(INDEX('Data-Input'!$C$190:$C$1189,MATCH(A6&"|"&$A$1,'Data-Input'!$E$190:$E$1189,0)),Q6) -> 20 | S6: =IF(OR($A$1="",A6=$A$1),-1000000000000000,R6) -> 20 | T6: =S6+ROW()*0.0000001 -> 20.000001 | U6: =Heroes!$M6 -> Mid Lane | V6: =IF(OR($A$1="",A6=$A$1,U6="",U6<>$J$1),-1000000000000000,R6)+ROW()*0.0000001 -> -1e+15 | W6: =Heroes!$I6 -> Poke | X6: =Heroes!$J6 -> Soft CC | Y6: =IF($A$1="",0,MAX(IF(W6<>"",IFERROR(INDEX('Data-Input'!$B$164:$W$185,MATCH(W6,'Data-Input'!$A$164:$A$185,0),MATCH($K$1,'Data-Input'!$B$163:$W$163,0)),0),0),IF(AND(W6<>"",$L$1<>""),IFERROR(INDEX('Data-Input'!$B$164:$W$185,MATCH(W6,'Data-Input'!$A$164:$A$185,0),MATCH($L$1,'Data-Input'!$B$163:$W$163,0)),0),0),IF(X6<>"",IFERROR(INDEX('Data-Input'!$B$164:$W$185,MATCH(X6,'Data-Input'!$A$164:$A$185,0),MATCH($K$1,'Data-Input'!$B$163:$W$163,0)),0),0),IF(AND(X6<>"",$L$1<>""),IFERROR(INDEX('Data-Input'!$B$164:$W$185,MATCH(X6,'Data-Input'!$A$164:$A$185,0),MATCH($L$1,'Data-Input'!$B$163:$W$163,0)),0),0))*$M$1) -> 0 | Z6: =IF($A$1="",0,SUMPRODUCT(('Data-Input'!$A$29:$A$128=A6)*('Data-Input'!$B$29:$B$128="Tag")*((('Data-Input'!$C$29:$C$128=$K$1)+('Data-Input'!$C$29:$C$128=$L$1))>0)*('Data-Input'!$D$29:$D$128-'Data-Input'!$E$29:$E$128))+SUMPRODUCT(('Data-Input'!$A$29:$A$128=A6)*('Data-Input'!$B$29:$B$128="Hero")*('Data-Input'!$C$29:$C$128=$A$1)*('Data-Input'!$D$29:$D$128-'Data-Input'!$E$29:$E$128))) -> 0
A7: =Heroes!$B7 -> Tigreal | B7: =Heroes!$C7 -> Tank | C7: =Heroes!$D7 -> 0 | D7: =Heroes!$E7 -> 10 | E7: =Heroes!$F7 -> 100 | F7: =Heroes!$H7 -> 10 | G7: =Heroes!$K7 -> Physical | H7: =Heroes!$Q7 -> 2 | I7: =IFERROR(INDEX('Data-Input'!$B$19:$G$24,MATCH(B7,'Data-Input'!$A$19:$A$24,0),MATCH($B$1,'Data-Input'!$B$18:$G$18,0)),0) -> 0 | J7: =IF(C7<>"",IFERROR(INDEX('Data-Input'!$B$19:$G$24,MATCH(C7,'Data-Input'!$A$19:$A$24,0),MATCH($B$1,'Data-Input'!$B$18:$G$18,0)),0),I7) -> 0 | K7: =MAX(I7,J7) -> 0 | L7: =((D7+E7)/2-$C$1)*$H$1 -> 5.5 | M7: =F7-$D$1 -> 10 | N7: =IF(M7>20,M7*$I$1,0) -> 0 | O7: =IF(G7="Mixed",$Q$1,IF(G7=$E$1,$O$1,$P$1)) -> 3 | P7: =(H7-$F$1)*$N$1 -> 6 | Q7: =K7*$G$1+L7+N7+O7+P7+Y7+Z7 -> 14.5 | R7: =IFERROR(INDEX('Data-Input'!$C$190:$C$1189,MATCH(A7&"|"&$A$1,'Data-Input'!$E$190:$E$1189,0)),Q7) -> 14.5 | S7: =IF(OR($A$1="",A7=$A$1),-1000000000000000,R7) -> 14.5 | T7: =S7+ROW()*0.0000001 -> 14.500001 | U7: =Heroes!$M7 -> Roaming | V7: =IF(OR($A$1="",A7=$A$1,U7="",U7<>$J$1),-1000000000000000,R7)+ROW()*0.0000001 -> -1e+15 | W7: =Heroes!$I7 -> AoE CC | X7: =Heroes!$J7 -> Hard CC | Y7: =IF($A$1="",0,MAX(IF(W7<>"",IFERROR(INDEX('Data-Input'!$B$164:$W$185,MATCH(W7,'Data-Input'!$A$164:$A$185,0),MATCH($K$1,'Data-Input'!$B$163:$W$163,0)),0),0),IF(AND(W7<>"",$L$1<>""),IFERROR(INDEX('Data-Input'!$B$164:$W$185,MATCH(W7,'Data-Input'!$A$164:$A$185,0),MATCH($L$1,'Data-Input'!$B$163:$W$163,0)),0),0),IF(X7<>"",IFERROR(INDEX('Data-Input'!$B$164:$W$185,MATCH(X7,'Data-Input'!$A$164:$A$185,0),MATCH($K$1,'Data-Input'!$B$163:$W$163,0)),0),0),IF(AND(X7<>"",$L$1<>""),IFERROR(INDEX('Data-Input'!$B$164:$W$185,MATCH(X7,'Data-Input'!$A$164:$A$185,0),MATCH($L$1,'Data-Input'!$B$163:$W$163,0)),0),0))*$M$1) -> 0 | Z7: =IF($A$1="",0,SUMPRODUCT(('Data-Input'!$A$29:$A$128=A7)*('Data-Input'!$B$29:$B$128="Tag")*((('Data-Input'!$C$29:$C$128=$K$1)+('Data-Input'!$C$29:$C$128=$L$1))>0)*('Data-Input'!$D$29:$D$128-'Data-Input'!$E$29:$E$128))+SUMPRODUCT(('Data-Input'!$A$29:$A$128=A7)*('Data-Input'!$B$29:$B$128="Hero")*('Data-Input'!$C$29:$C$128=$A$1)*('Data-Input'!$D$29:$D$128-'Data-Input'!$E$29:$E$128))) -> 0
A8: =Heroes!$B8 -> Alucard | B8: =Heroes!$C8 -> Fighter | C8: =Heroes!$D8 -> Assassin | D8: =Heroes!$E8 -> 50 | E8: =Heroes!$F8 -> 10 | F8: =Heroes!$H8 -> 40 | G8: =Heroes!$K8 -> Physical | H8: =Heroes!$Q8 -> 3 | I8: =IFERROR(INDEX('Data-Input'!$B$19:$G$24,MATCH(B8,'Data-Input'!$A$19:$A$24,0),MATCH($B$1,'Data-Input'!$B$18:$G$18,0)),0) -> 0 | J8: =IF(C8<>"",IFERROR(INDEX('Data-Input'!$B$19:$G$24,MATCH(C8,'Data-Input'!$A$19:$A$24,0),MATCH($B$1,'Data-Input'!$B$18:$G$18,0)),0),I8) -> 0 | K8: =MAX(I8,J8) -> 0 | L8: =((D8+E8)/2-$C$1)*$H$1 -> 3 | M8: =F8-$D$1 -> 40 | N8: =IF(M8>20,M8*$I$1,0) -> 12 | O8: =IF(G8="Mixed",$Q$1,IF(G8=$E$1,$O$1,$P$1)) -> 3 | P8: =(H8-$F$1)*$N$1 -> 9 | Q8: =K8*$G$1+L8+N8+O8+P8+Y8+Z8 -> 27 | R8: =IFERROR(INDEX('Data-Input'!$C$190:$C$1189,MATCH(A8&"|"&$A$1,'Data-Input'!$E$190:$E$1189,0)),Q8) -> 27 | S8: =IF(OR($A$1="",A8=$A$1),-1000000000000000,R8) -> 27 | T8: =S8+ROW()*0.0000001 -> 27.000001 | U8: =Heroes!$M8 -> Jungle | V8: =IF(OR($A$1="",A8=$A$1,U8="",U8<>$J$1),-1000000000000000,R8)+ROW()*0.0000001 -> -1e+15 | W8: =Heroes!$I8 -> Sustain | X8: =Heroes!$J8 -> DPS | Y8: =IF($A$1="",0,MAX(IF(W8<>"",IFERROR(INDEX('Data-Input'!$B$164:$W$185,MATCH(W8,'Data-Input'!$A$164:$A$185,0),MATCH($K$1,'Data-Input'!$B$163:$W$163,0)),0),0),IF(AND(W8<>"",$L$1<>""),IFERROR(INDEX('Data-Input'!$B$164:$W$185,MATCH(W8,'Data-Input'!$A$164:$A$185,0),MATCH($L$1,'Data-Input'!$B$163:$W$163,0)),0),0),IF(X8<>"",IFERROR(INDEX('Data-Input'!$B$164:$W$185,MATCH(X8,'Data-Input'!$A$164:$A$185,0),MATCH($K$1,'Data-Input'!$B$163:$W$163,0)),0),0),IF(AND(X8<>"",$L$1<>""),IFERROR(INDEX('Data-Input'!$B$164:$W$185,MATCH(X8,'Data-Input'!$A$164:$A$185,0),MATCH($L$1,'Data-Input'!$B$163:$W$163,0)),0),0))*$M$1) -> 0 | Z8: =IF($A$1="",0,SUMPRODUCT(('Data-Input'!$A$29:$A$128=A8)*('Data-Input'!$B$29:$B$128="Tag")*((('Data-Input'!$C$29:$C$128=$K$1)+('Data-Input'!$C$29:$C$128=$L$1))>0)*('Data-Input'!$D$29:$D$128-'Data-Input'!$E$29:$E$128))+SUMPRODUCT(('Data-Input'!$A$29:$A$128=A8)*('Data-Input'!$B$29:$B$128="Hero")*('Data-Input'!$C$29:$C$128=$A$1)*('Data-Input'!$D$29:$D$128-'Data-Input'!$E$29:$E$128))) -> 0
A9: =Heroes!$B9 -> Karina | B9: =Heroes!$C9 -> Assassin | C9: =Heroes!$D9 -> 0 | D9: =Heroes!$E9 -> 70 | E9: =Heroes!$F9 -> 10 | F9: =Heroes!$H9 -> 40 | G9: =Heroes!$K9 -> Magic | H9: =Heroes!$Q9 -> 2 | I9: =IFERROR(INDEX('Data-Input'!$B$19:$G$24,MATCH(B9,'Data-Input'!$A$19:$A$24,0),MATCH($B$1,'Data-Input'!$B$18:$G$18,0)),0) -> 0 | J9: =IF(C9<>"",IFERROR(INDEX('Data-Input'!$B$19:$G$24,MATCH(C9,'Data-Input'!$A$19:$A$24,0),MATCH($B$1,'Data-Input'!$B$18:$G$18,0)),0),I9) -> 0 | K9: =MAX(I9,J9) -> 0 | L9: =((D9+E9)/2-$C$1)*$H$1 -> 4 | M9: =F9-$D$1 -> 40 | N9: =IF(M9>20,M9*$I$1,0) -> 12 | O9: =IF(G9="Mixed",$Q$1,IF(G9=$E$1,$O$1,$P$1)) -> 3 | P9: =(H9-$F$1)*$N$1 -> 6 | Q9: =K9*$G$1+L9+N9+O9+P9+Y9+Z9 -> 25 | R9: =IFERROR(INDEX('Data-Input'!$C$190:$C$1189,MATCH(A9&"|"&$A$1,'Data-Input'!$E$190:$E$1189,0)),Q9) -> 25 | S9: =IF(OR($A$1="",A9=$A$1),-1000000000000000,R9) -> 25 | T9: =S9+ROW()*0.0000001 -> 25.000001 | U9: =Heroes!$M9 -> Jungle | V9: =IF(OR($A$1="",A9=$A$1,U9="",U9<>$J$1),-1000000000000000,R9)+ROW()*0.0000001 -> -1e+15 | W9: =Heroes!$I9 -> Burst | X9: =Heroes!$J9 -> Execute | Y9: =IF($A$1="",0,MAX(IF(W9<>"",IFERROR(INDEX('Data-Input'!$B$164:$W$185,MATCH(W9,'Data-Input'!$A$164:$A$185,0),MATCH($K$1,'Data-Input'!$B$163:$W$163,0)),0),0),IF(AND(W9<>"",$L$1<>""),IFERROR(INDEX('Data-Input'!$B$164:$W$185,MATCH(W9,'Data-Input'!$A$164:$A$185,0),MATCH($L$1,'Data-Input'!$B$163:$W$163,0)),0),0),IF(X9<>"",IFERROR(INDEX('Data-Input'!$B$164:$W$185,MATCH(X9,'Data-Input'!$A$164:$A$185,0),MATCH($K$1,'Data-Input'!$B$163:$W$163,0)),0),0),IF(AND(X9<>"",$L$1<>""),IFERROR(INDEX('Data-Input'!$B$164:$W$185,MATCH(X9,'Data-Input'!$A$164:$A$185,0),MATCH($L$1,'Data-Input'!$B$163:$W$163,0)),0),0))*$M$1) -> 0 | Z9: =IF($A$1="",0,SUMPRODUCT(('Data-Input'!$A$29:$A$128=A9)*('Data-Input'!$B$29:$B$128="Tag")*((('Data-Input'!$C$29:$C$128=$K$1)+('Data-Input'!$C$29:$C$128=$L$1))>0)*('Data-Input'!$D$29:$D$128-'Data-Input'!$E$29:$E$128))+SUMPRODUCT(('Data-Input'!$A$29:$A$128=A9)*('Data-Input'!$B$29:$B$128="Hero")*('Data-Input'!$C$29:$C$128=$A$1)*('Data-Input'!$D$29:$D$128-'Data-Input'!$E$29:$E$128))) -> 0
A10: =Heroes!$B10 -> Akai | B10: =Heroes!$C10 -> Tank | C10: =Heroes!$D10 -> 0 | D10: =Heroes!$E10 -> 30 | E10: =Heroes!$F10 -> 90 | F10: =Heroes!$H10 -> 30 | G10: =Heroes!$K10 -> Physical | H10: =Heroes!$Q10 -> 2 | I10: =IFERROR(INDEX('Data-Input'!$B$19:$G$24,MATCH(B10,'Data-Input'!$A$19:$A$24,0),MATCH($B$1,'Data-Input'!$B$18:$G$18,0)),0) -> 0 | J10: =IF(C10<>"",IFERROR(INDEX('Data-Input'!$B$19:$G$24,MATCH(C10,'Data-Input'!$A$19:$A$24,0),MATCH($B$1,'Data-Input'!$B$18:$G$18,0)),0),I10) -> 0 | K10: =MAX(I10,J10) -> 0 | L10: =((D10+E10)/2-$C$1)*$H$1 -> 6 | M10: =F10-$D$1 -> 30 | N10: =IF(M10>20,M10*$I$1,0) -> 9 | O10: =IF(G10="Mixed",$Q$1,IF(G10=$E$1,$O$1,$P$1)) -> 3 | P10: =(H10-$F$1)*$N$1 -> 6 | Q10: =K10*$G$1+L10+N10+O10+P10+Y10+Z10 -> 24 | R10: =IFERROR(INDEX('Data-Input'!$C$190:$C$1189,MATCH(A10&"|"&$A$1,'Data-Input'!$E$190:$E$1189,0)),Q10) -> 24 | S10: =IF(OR($A$1="",A10=$A$1),-1000000000000000,R10) -> 24 | T10: =S10+ROW()*0.0000001 -> 24.000001 | U10: =Heroes!$M10 -> Roaming | V10: =IF(OR($A$1="",A10=$A$1,U10="",U10<>$J$1),-1000000000000000,R10)+ROW()*0.0000001 -> -1e+15 | W10: =Heroes!$I10 -> Hard CC | X10: =Heroes!$J10 -> Shield | Y10: =IF($A$1="",0,MAX(IF(W10<>"",IFERROR(INDEX('Data-Input'!$B$164:$W$185,MATCH(W10,'Data-Input'!$A$164:$A$185,0),MATCH($K$1,'Data-Input'!$B$163:$W$163,0)),0),0),IF(AND(W10<>"",$L$1<>""),IFERROR(INDEX('Data-Input'!$B$164:$W$185,MATCH(W10,'Data-Input'!$A$164:$A$185,0),MATCH($L$1,'Data-Input'!$B$163:$W$163,0)),0),0),IF(X10<>"",IFERROR(INDEX('Data-Input'!$B$164:$W$185,MATCH(X10,'Data-Input'!$A$164:$A$185,0),MATCH($K$1,'Data-Input'!$B$163:$W$163,0)),0),0),IF(AND(X10<>"",$L$1<>""),IFERROR(INDEX('Data-Input'!$B$164:$W$185,MATCH(X10,'Data-Input'!$A$164:$A$185,0),MATCH($L$1,'Data-Input'!$B$163:$W$163,0)),0),0))*$M$1) -> 0 | Z10: =IF($A$1="",0,SUMPRODUCT(('Data-Input'!$A$29:$A$128=A10)*('Data-Input'!$B$29:$B$128="Tag")*((('Data-Input'!$C$29:$C$128=$K$1)+('Data-Input'!$C$29:$C$128=$L$1))>0)*('Data-Input'!$D$29:$D$128-'Data-Input'!$E$29:$E$128))+SUMPRODUCT(('Data-Input'!$A$29:$A$128=A10)*('Data-Input'!$B$29:$B$128="Hero")*('Data-Input'!$C$29:$C$128=$A$1)*('Data-Input'!$D$29:$D$128-'Data-Input'!$E$29:$E$128))) -> 0
A11: =Heroes!$B11 -> Franco | B11: =Heroes!$C11 -> Tank | C11: =Heroes!$D11 -> 0 | D11: =Heroes!$E11 -> 10 | E11: =Heroes!$F11 -> 100 | F11: =Heroes!$H11 -> 20 | G11: =Heroes!$K11 -> Physical | H11: =Heroes!$Q11 -> 2 | I11: =IFERROR(INDEX('Data-Input'!$B$19:$G$24,MATCH(B11,'Data-Input'!$A$19:$A$24,0),MATCH($B$1,'Data-Input'!$B$18:$G$18,0)),0) -> 0 | J11: =IF(C11<>"",IFERROR(INDEX('Data-Input'!$B$19:$G$24,MATCH(C11,'Data-Input'!$A$19:$A$24,0),MATCH($B$1,'Data-Input'!$B$18:$G$18,0)),0),I11) -> 0 | K11: =MAX(I11,J11) -> 0 | L11: =((D11+E11)/2-$C$1)*$H$1 -> 5.5 | M11: =F11-$D$1 -> 20 | N11: =IF(M11>20,M11*$I$1,0) -> 0 | O11: =IF(G11="Mixed",$Q$1,IF(G11=$E$1,$O$1,$P$1)) -> 3 | P11: =(H11-$F$1)*$N$1 -> 6 | Q11: =K11*$G$1+L11+N11+O11+P11+Y11+Z11 -> 14.5 | R11: =IFERROR(INDEX('Data-Input'!$C$190:$C$1189,MATCH(A11&"|"&$A$1,'Data-Input'!$E$190:$E$1189,0)),Q11) -> 14.5 | S11: =IF(OR($A$1="",A11=$A$1),-1000000000000000,R11) -> 14.5 | T11: =S11+ROW()*0.0000001 -> 14.500001 | U11: =Heroes!$M11 -> Roaming | V11: =IF(OR($A$1="",A11=$A$1,U11="",U11<>$J$1),-1000000000000000,R11)+ROW()*0.0000001 -> -1e+15 | W11: =Heroes!$I11 -> Targeted CC | X11: =Heroes!$J11 -> Hard CC | Y11: =IF($A$1="",0,MAX(IF(W11<>"",IFERROR(INDEX('Data-Input'!$B$164:$W$185,MATCH(W11,'Data-Input'!$A$164:$A$185,0),MATCH($K$1,'Data-Input'!$B$163:$W$163,0)),0),0),IF(AND(W11<>"",$L$1<>""),IFERROR(INDEX('Data-Input'!$B$164:$W$185,MATCH(W11,'Data-Input'!$A$164:$A$185,0),MATCH($L$1,'Data-Input'!$B$163:$W$163,0)),0),0),IF(X11<>"",IFERROR(INDEX('Data-Input'!$B$164:$W$185,MATCH(X11,'Data-Input'!$A$164:$A$185,0),MATCH($K$1,'Data-Input'!$B$163:$W$163,0)),0),0),IF(AND(X11<>"",$L$1<>""),IFERROR(INDEX('Data-Input'!$B$164:$W$185,MATCH(X11,'Data-Input'!$A$164:$A$185,0),MATCH($L$1,'Data-Input'!$B$163:$W$163,0)),0),0))*$M$1) -> 0 | Z11: =IF($A$1="",0,SUMPRODUCT(('Data-Input'!$A$29:$A$128=A11)*('Data-Input'!$B$29:$B$128="Tag")*((('Data-Input'!$C$29:$C$128=$K$1)+('Data-Input'!$C$29:$C$128=$L$1))>0)*('Data-Input'!$D$29:$D$128-'Data-Input'!$E$29:$E$128))+SUMPRODUCT(('Data-Input'!$A$29:$A$128=A11)*('Data-Input'!$B$29:$B$128="Hero")*('Data-Input'!$C$29:$C$128=$A$1)*('Data-Input'!$D$29:$D$128-'Data-Input'!$E$29:$E$128))) -> 0
A12: =Heroes!$B12 -> Bane | B12: =Heroes!$C12 -> Fighter | C12: =Heroes!$D12 -> Mage | D12: =Heroes!$E12 -> 60 | E12: =Heroes!$F12 -> 40 | F12: =Heroes!$H12 -> 30 | G12: =Heroes!$K12 -> Mixed | H12: =Heroes!$Q12 -> 3 | I12: =IFERROR(INDEX('Data-Input'!$B$19:$G$24,MATCH(B12,'Data-Input'!$A$19:$A$24,0),MATCH($B$1,'Data-Input'!$B$18:$G$18,0)),0) -> 0 | J12: =IF(C12<>"",IFERROR(INDEX('Data-Input'!$B$19:$G$24,MATCH(C12,'Data-Input'!$A$19:$A$24,0),MATCH($B$1,'Data-Input'!$B$18:$G$18,0)),0),I12) -> 0 | K12: =MAX(I12,J12) -> 0 | L12: =((D12+E12)/2-$C$1)*$H$1 -> 5 | M12: =F12-$D$1 -> 30 | N12: =IF(M12>20,M12*$I$1,0) -> 9 | O12: =IF(G12="Mixed",$Q$1,IF(G12=$E$1,$O$1,$P$1)) -> 5 | P12: =(H12-$F$1)*$N$1 -> 9 | Q12: =K12*$G$1+L12+N12+O12+P12+Y12+Z12 -> 28 | R12: =IFERROR(INDEX('Data-Input'!$C$190:$C$1189,MATCH(A12&"|"&$A$1,'Data-Input'!$E$190:$E$1189,0)),Q12) -> 28 | S12: =IF(OR($A$1="",A12=$A$1),-1000000000000000,R12) -> 28 | T12: =S12+ROW()*0.0000001 -> 28.000001 | U12: =Heroes!$M12 -> Jungle | V12: =IF(OR($A$1="",A12=$A$1,U12="",U12<>$J$1),-1000000000000000,R12)+ROW()*0.0000001 -> -1e+15 | W12: =Heroes!$I12 -> Poke | X12: =Heroes!$J12 -> AoE Damage | Y12: =IF($A$1="",0,MAX(IF(W12<>"",IFERROR(INDEX('Data-Input'!$B$164:$W$185,MATCH(W12,'Data-Input'!$A$164:$A$185,0),MATCH($K$1,'Data-Input'!$B$163:$W$163,0)),0),0),IF(AND(W12<>"",$L$1<>""),IFERROR(INDEX('Data-Input'!$B$164:$W$185,MATCH(W12,'Data-Input'!$A$164:$A$185,0),MATCH($L$1,'Data-Input'!$B$163:$W$163,0)),0),0),IF(X12<>"",IFERROR(INDEX('Data-Input'!$B$164:$W$185,MATCH(X12,'Data-Input'!$A$164:$A$185,0),MATCH($K$1,'Data-Input'!$B$163:$W$163,0)),0),0),IF(AND(X12<>"",$L$1<>""),IFERROR(INDEX('Data-Input'!$B$164:$W$185,MATCH(X12,'Data-Input'!$A$164:$A$185,0),MATCH($L$1,'Data-Input'!$B$163:$W$163,0)),0),0))*$M$1) -> 0 | Z12: =IF($A$1="",0,SUMPRODUCT(('Data-Input'!$A$29:$A$128=A12)*('Data-Input'!$B$29:$B$128="Tag")*((('Data-Input'!$C$29:$C$128=$K$1)+('Data-Input'!$C$29:$C$128=$L$1))>0)*('Data-Input'!$D$29:$D$128-'Data-Input'!$E$29:$E$128))+SUMPRODUCT(('Data-Input'!$A$29:$A$128=A12)*('Data-Input'!$B$29:$B$128="Hero")*('Data-Input'!$C$29:$C$128=$A$1)*('Data-Input'!$D$29:$D$128-'Data-Input'!$E$29:$E$128))) -> 0
A13: =Heroes!$B13 -> Bruno | B13: =Heroes!$C13 -> Marksman | C13: =Heroes!$D13 -> 0 | D13: =Heroes!$E13 -> 60 | E13: =Heroes!$F13 -> 20 | F13: =Heroes!$H13 -> 50 | G13: =Heroes!$K13 -> Physical | H13: =Heroes!$Q13 -> 5 | I13: =IFERROR(INDEX('Data-Input'!$B$19:$G$24,MATCH(B13,'Data-Input'!$A$19:$A$24,0),MATCH($B$1,'Data-Input'!$B$18:$G$18,0)),0) -> 0 | J13: =IF(C13<>"",IFERROR(INDEX('Data-Input'!$B$19:$G$24,MATCH(C13,'Data-Input'!$A$19:$A$24,0),MATCH($B$1,'Data-Input'!$B$18:$G$18,0)),0),I13) -> 0 | K13: =MAX(I13,J13) -> 0 | L13: =((D13+E13)/2-$C$1)*$H$1 -> 4 | M13: =F13-$D$1 -> 50 | N13: =IF(M13>20,M13*$I$1,0) -> 15 | O13: =IF(G13="Mixed",$Q$1,IF(G13=$E$1,$O$1,$P$1)) -> 3 | P13: =(H13-$F$1)*$N$1 -> 15 | Q13: =K13*$G$1+L13+N13+O13+P13+Y13+Z13 -> 37 | R13: =IFERROR(INDEX('Data-Input'!$C$190:$C$1189,MATCH(A13&"|"&$A$1,'Data-Input'!$E$190:$E$1189,0)),Q13) -> 37 | S13: =IF(OR($A$1="",A13=$A$1),-1000000000000000,R13) -> 37 | T13: =S13+ROW()*0.0000001 -> 37.000001 | U13: =Heroes!$M13 -> Gold Lane | V13: =IF(OR($A$1="",A13=$A$1,U13="",U13<>$J$1),-1000000000000000,R13)+ROW()*0.0000001 -> -1e+15 | W13: =Heroes!$I13 -> DPS | X13: =Heroes!$J13 -> Burst | Y13: =IF($A$1="",0,MAX(IF(W13<>"",IFERROR(INDEX('Data-Input'!$B$164:$W$185,MATCH(W13,'Data-Input'!$A$164:$A$185,0),MATCH($K$1,'Data-Input'!$B$163:$W$163,0)),0),0),IF(AND(W13<>"",$L$1<>""),IFERROR(INDEX('Data-Input'!$B$164:$W$185,MATCH(W13,'Data-Input'!$A$164:$A$185,0),MATCH($L$1,'Data-Input'!$B$163:$W$163,0)),0),0),IF(X13<>"",IFERROR(INDEX('Data-Input'!$B$164:$W$185,MATCH(X13,'Data-Input'!$A$164:$A$185,0),MATCH($K$1,'Data-Input'!$B$163:$W$163,0)),0),0),IF(AND(X13<>"",$L$1<>""),IFERROR(INDEX('Data-Input'!$B$164:$W$185,MATCH(X13,'Data-Input'!$A$164:$A$185,0),MATCH($L$1,'Data-Input'!$B$163:$W$163,0)),0),0))*$M$1) -> 0 | Z13: =IF($A$1="",0,SUMPRODUCT(('Data-Input'!$A$29:$A$128=A13)*('Data-Input'!$B$29:$B$128="Tag")*((('Data-Input'!$C$29:$C$128=$K$1)+('Data-Input'!$C$29:$C$128=$L$1))>0)*('Data-Input'!$D$29:$D$128-'Data-Input'!$E$29:$E$128))+SUMPRODUCT(('Data-Input'!$A$29:$A$128=A13)*('Data-Input'!$B$29:$B$128="Hero")*('Data-Input'!$C$29:$C$128=$A$1)*('Data-Input'!$D$29:$D$128-'Data-Input'!$E$29:$E$128))) -> 0
... A134: =Heroes!$B134 -> Hirara | B134: =Heroes!$C134 -> Assassin | C134: =Heroes!$D134 -> 0 | D134: =Heroes!$E134 -> 80 | E134: =Heroes!$F134 -> 40 | F134: =Heroes!$H134 -> 70 | G134: =Heroes!$K134 -> Physical | H134: =Heroes!$Q134 -> 2 | I134: =IFERROR(INDEX('Data-Input'!$B$19:$G$24,MATCH(B134,'Data-Input'!$A$19:$A$24,0),MATCH($B$1,'Data-Input'!$B$18:$G$18,0)),0) -> 0 | J134: =IF(C134<>"",IFERROR(INDEX('Data-Input'!$B$19:$G$24,MATCH(C134,'Data-Input'!$A$19:$A$24,0),MATCH($B$1,'Data-Input'!$B$18:$G$18,0)),0),I134) -> 0 | K134: =MAX(I134,J134) -> 0 | L134: =((D134+E134)/2-$C$1)*$H$1 -> 6 | M134: =F134-$D$1 -> 70 | N134: =IF(M134>20,M134*$I$1,0) -> 21 | O134: =IF(G134="Mixed",$Q$1,IF(G134=$E$1,$O$1,$P$1)) -> 3 | P134: =(H134-$F$1)*$N$1 -> 6 | Q134: =K134*$G$1+L134+N134+O134+P134+Y134+Z134 -> 36 | R134: =IFERROR(INDEX('Data-Input'!$C$190:$C$1189,MATCH(A134&"|"&$A$1,'Data-Input'!$E$190:$E$1189,0)),Q134) -> 36 | S134: =IF(OR($A$1="",A134=$A$1),-1000000000000000,R134) -> 36 | T134: =S134+ROW()*0.0000001 -> 36.000013 | U134: =Heroes!$M134 -> Jungle | V134: =IF(OR($A$1="",A134=$A$1,U134="",U134<>$J$1),-1000000000000000,R134)+ROW()*0.0000001 -> -1e+15 | W134: =Heroes!$I134 -> Burst | X134: =Heroes!$J134 -> High Mobility | Y134: =IF($A$1="",0,MAX(IF(W134<>"",IFERROR(INDEX('Data-Input'!$B$164:$W$185,MATCH(W134,'Data-Input'!$A$164:$A$185,0),MATCH($K$1,'Data-Input'!$B$163:$W$163,0)),0),0),IF(AND(W134<>"",$L$1<>""),IFERROR(INDEX('Data-Input'!$B$164:$W$185,MATCH(W134,'Data-Input'!$A$164:$A$185,0),MATCH($L$1,'Data-Input'!$B$163:$W$163,0)),0),0),IF(X134<>"",IFERROR(INDEX('Data-Input'!$B$164:$W$185,MATCH(X134,'Data-Input'!$A$164:$A$185,0),MATCH($K$1,'Data-Input'!$B$163:$W$163,0)),0),0),IF(AND(X134<>"",$L$1<>""),IFERROR(INDEX('Data-Input'!$B$164:$W$185,MATCH(X134,'Data-Input'!$A$164:$A$185,0),MATCH($L$1,'Data-Input'!$B$163:$W$163,0)),0),0))*$M$1) -> 0 | Z134: =IF($A$1="",0,SUMPRODUCT(('Data-Input'!$A$29:$A$128=A134)*('Data-Input'!$B$29:$B$128="Tag")*((('Data-Input'!$C$29:$C$128=$K$1)+('Data-Input'!$C$29:$C$128=$L$1))>0)*('Data-Input'!$D$29:$D$128-'Data-Input'!$E$29:$E$128))+SUMPRODUCT(('Data-Input'!$A$29:$A$128=A134)*('Data-Input'!$B$29:$B$128="Hero")*('Data-Input'!$C$29:$C$128=$A$1)*('Data-Input'!$D$29:$D$128-'Data-Input'!$E$29:$E$128))) -> 0
